<?xml version = "1.0"?>

<robot name = "ROSMASTER_X1" xmlns:xacro="http://www.ros.org/wiki/xacro">
    <!--If ROS2 Humble then is_ignition = true, set to false if higher than ROS2 Humble-->
    <!-- This is done to adapt the URDF model to the ROS2 version used-->
    <xacro:arg name="is_ignition" default="false"/> 

    <!-- Include Gazebo Parameters -->
    <xacro:include filename="$(find x1_description)/urdf/x1_gazebo.xacro" />

    <!-- Include Gazebo Control Plugins (defined in the ros2 controller package) -->
    <xacro:include filename="$(find x1_description)/urdf/x1_ros2_control.xacro"/>

    <!-- Material definitions -->
    <material name="Green">
        <color rgba="0 0.7 0 1"/>
    </material>
    <material name="White">
        <color rgba="0.9 0.9 0.9 1"/>
    </material>

    <!-- Base links -->
    <link name="base_footprint"/>

    <!-- Common link macro -->
    <xacro:macro name="common_link" params="name material path *origin collision_shape collision_size collision_xyz:='0 0 0'">
        <link name="${name}">
            <visual>
                <geometry>
                    <mesh filename="package://x1_description/meshes/${path}/${name}.STL"/>
                </geometry>
                <origin xyz="0 0 0" rpy="0 0 0"/>
                <material name="${material}"/>
            </visual>
            <collision>
                <geometry>
                    <xacro:if value="${collision_shape == 'box'}">
                        <box size="${collision_size}"/>
                    </xacro:if>
                    <xacro:if value="${collision_shape == 'cylinder'}">
                        <cylinder radius="${collision_size.split()[0]}" length="${collision_size.split()[1]}"/>
                    </xacro:if>
                </geometry>
                <origin xyz="${collision_xyz}" rpy="0 0 0"/>
            </collision>
            <xacro:insert_block name="origin"/>
        </link>
    </xacro:macro>

    <!-- Continuous joint macro -->
    <xacro:macro name="continuous_joint" params="name parent child xyz rpy axis">
        <joint name="${name}" type="continuous">
            <parent link="${parent}"/>
            <child link="${child}"/>
            <origin xyz="${xyz}" rpy="${rpy}"/>
            <axis xyz="${axis}"/>
            <limit lower="${-pi}" upper="${pi}" effort="100" velocity="1"/>
            <dynamics friction="1E-04"/>
        </joint>
    </xacro:macro>

    <!-- Fixed joint macro -->
    <xacro:macro name="fixed_joint" params="name parent child xyz rpy">
        <joint name="${name}" type="fixed">
            <parent link="${parent}"/>
            <child link="${child}"/>
            <origin xyz="${xyz}" rpy="${rpy}"/>
        </joint>
    </xacro:macro>

    <!-- Base Link -->
    <xacro:common_link name="base_link" material="Green" path="mecanum" collision_shape="box" collision_size="0.2235 0.139 0.1165" collision_xyz='0.005 0 0.0025    '>
        <inertial>
            <origin xyz="0.00498197982182523 5.70233829969297E-05 -0.0121008098068578" rpy="0 0 0"/>
            <mass value="0.486218814966626"/>
            <inertia
                ixx="0.00196277727666921"
                ixy="2.50447049446755E-07"
                ixz="0.000140534767811098"
                iyy="0.00457256033711368"
                iyz="2.68618064993882E-07"
                izz="0.00493927269870476"/>
        </inertial>
    </xacro:common_link>

    <!-- Fixed Joints -->
    <xacro:fixed_joint name="base_joint" parent="base_footprint" child="base_link" xyz="0.0 0.0 0.0850" rpy="0 0 0"/>
    
    <link name="imu_link"/>
    <xacro:fixed_joint name="base_imu" parent="base_link" child="imu_link" xyz="-0.06 0.01 0.01" rpy="0 3.1415 1.5707"/>

    <!-- Wheels -->
    <xacro:common_link name="front_right_wheel" material="White" path="mecanum" collision_shape="cylinder" collision_size="0.035 0.03">
        <inertial>
            <origin xyz="1.9051E-06 -2.3183E-07 -0.00064079" rpy="0 0 0"/>
            <mass value="0.051532"/>
            <inertia ixx="1.4595E-05" ixy="-4.3975E-10" ixz="4.415E-10"
                     iyy="1.4594E-05" iyz="-1.7476E-09" izz="2.4264E-05"/>
        </inertial>
    </xacro:common_link>
    <xacro:continuous_joint name="front_right_joint" parent="base_link" child="front_right_wheel"
                      xyz="0.08 -0.0845 -0.0389" rpy="-${pi/2} 0 0" axis="0 0 1"/>
    
    <xacro:common_link name="front_left_wheel" material="White" path="mecanum" collision_shape="cylinder" collision_size="0.035 0.03">
        <inertial>
            <origin xyz="2.3728E-06 -9.4228E-07 0.00064068" rpy="0 0 0"/>
            <mass value="0.051543"/>
            <inertia ixx="1.4597E-05" ixy="-4.7945E-10" ixz="-2.4786E-10"
                     iyy="1.4598E-05" iyz="1.7972E-09" izz="2.4267E-05"/>
        </inertial>
    </xacro:common_link>
    <xacro:continuous_joint name="front_left_joint" parent="base_link" child="front_left_wheel"
                      xyz="0.08 0.0845 -0.0389" rpy="${pi/2} 0 0" axis="0 0 -1"/>
    
    <xacro:common_link name="back_right_wheel" material="White" path="mecanum" collision_shape="cylinder" collision_size="0.035 0.03">
        <inertial>
            <origin xyz="-1.75924169923403E-06 1.28388821071107E-06 -0.000590549296238266" rpy="0 0 0"/>
            <mass value="0.051540174053366"/>
            <inertia ixx="1.45974152250002E-05" ixy="1.94850559178397E-10" ixz="-1.61846387282284E-09"
                     iyy="1.4596501955693E-05" iyz="-6.27904057423818E-10" izz="2.42663091380451E-05"/>
        </inertial>
    </xacro:common_link>
    <xacro:continuous_joint name="back_right_joint" parent="base_link" child="back_right_wheel"
                      xyz="-0.08 -0.0845 -0.0395" rpy="-${pi/2} 0 0" axis="0 0 1"/>
    
    <xacro:common_link name="back_left_wheel" material="White" path="mecanum" collision_shape="cylinder" collision_size="0.035 0.03">
        <inertial>
            <origin xyz="-4.01213085227115E-07 2.04910264598596E-06 0.000590775697051377" rpy="0 0 0"/>
            <mass value="0.0515309299357028"/>
            <inertia ixx="1.45942986129926E-05" ixy="-3.19787215398093E-10" ixz="1.74943062058915E-09"
                     iyy="1.45948727598913E-05" iyz="1.61769812110049E-10" izz="2.4263683888153E-05"/>
        </inertial>
    </xacro:common_link>
    <xacro:continuous_joint name="back_left_joint" parent="base_link" child="back_left_wheel"
                      xyz="-0.08 0.0845 -0.0395" rpy="${pi/2} 0 0" axis="0 0 -1"/>

    <!-- Sensors -->
    <xacro:include filename="lidar.xacro"/>

    <xacro:common_link name="camera_link" material="White" path="sensor" collision_shape="box" collision_size="0.06 0.17 0.05">
        <inertial>
            <origin xyz="0 0 0" rpy="0 0 0"/>
            <mass value="0"/>
            <inertia ixx="0" ixy="0" ixz="0" iyy="0" iyz="0" izz="0"/>
        </inertial>
    </xacro:common_link>
    <xacro:fixed_joint name="camera_joint" parent="base_link" child="camera_link" xyz="0.057105 1.7948E-05 0.03755" rpy="0 0 0"/>
</robot>
